<?xml version="1.0" ?>
<!-- =================================================================================== -->
<!-- |    This document was autogenerated by xacro from /home/user/difrobot_ws/src/difrobot_description/urdf/difrobot.urdf.xacro | -->
<!-- |    EDITING THIS FILE BY HAND IS NOT RECOMMENDED                                 | -->
<!-- =================================================================================== -->
<robot name="difrobot">
  <transmission name="wheel_right_transmission">
    <plugin>transmission_interface/SimpleTransmission</plugin>
    <actuator name="wheel_right_motor" role="actuator_right"/>
    <joint name="wheel_right_motor" role="joint_right">
      <mechanical_reduction>1.0</mechanical_reduction>
    </joint>
  </transmission>
  <transmission name="wheel_left_transmission">
    <plugin>transmission_interface/SimpleTransmission</plugin>
    <actuator name="wheel_left_motor" role="actuator_left"/>
    <joint name="wheel_left_motor" role="joint_left">
      <mechanical_reduction>1.0</mechanical_reduction>
    </joint>
  </transmission>
  <!-- Wheels -->
  <gazebo reference="wheel_left_link">
    <mu1>1000000000000000.0</mu1>
    <mu2>1000000000000000.0</mu2>
    <kp>1000000000000.0</kp>
    <kd>10.0</kd>
    <minDepth>0.001</minDepth>
    <maxVel>0.1</maxVel>
    <fdir1>1 0 0</fdir1>
  </gazebo>
  <gazebo reference="wheel_right_link">
    <mu1>1000000000000000.0</mu1>
    <mu2>1000000000000000.0</mu2>
    <kp>1000000000000.0</kp>
    <kd>10.0</kd>
    <minDepth>0.001</minDepth>
    <maxVel>0.1</maxVel>
    <fdir1>1 0 0</fdir1>
  </gazebo>
  <!-- Caster Wheels -->
  <gazebo reference="caster_rear_link">
    <mu1>0.1</mu1>
    <mu2>0.1</mu2>
    <kp>1000000.0</kp>
    <kd>100.0</kd>
    <minDepth>0.001</minDepth>
    <maxVel>1.0</maxVel>
  </gazebo>
  <gazebo reference="caster_front_link">
    <mu1>0.1</mu1>
    <mu2>0.1</mu2>
    <kp>1000000.0</kp>
    <kd>100.0</kd>
    <minDepth>0.001</minDepth>
    <maxVel>1.0</maxVel>
  </gazebo>
  <gazebo>
    <plugin filename="libgazebo_ros2_control.so" name="gazebo_ros2_control">
      <robot_param>robot_description</robot_param>
      <robot_param_node>robot_state_publisher</robot_param_node>
      <parameters>/home/user/difrobot_ws/install/difrobot_controller/share/difrobot_controller/config/difrobot_controllers.yaml</parameters>
    </plugin>
  </gazebo>
  <ros2_control name="RobotSystem" type="system">
    <!-- ros2_control Gazebo -->
    <hardware>
      <plugin>gazebo_ros2_control/GazeboSystem</plugin>
    </hardware>
    <!-- ros2_control Common Interfaces -->
    <joint name="wheel_right_joint">
      <command_interface name="velocity">
        <param name="min">-1</param>
        <param name="max">1</param>
      </command_interface>
      <state_interface name="position"/>
      <state_interface name="velocity"/>
    </joint>
    <joint name="wheel_left_joint">
      <command_interface name="velocity">
        <param name="min">-1</param>
        <param name="max">1</param>
      </command_interface>
      <state_interface name="position"/>
      <state_interface name="velocity"/>
    </joint>
  </ros2_control>
  <!-- Definir Materiales -->
  <material name="red">
    <color rgba="1 0 0 1"/>
  </material>
  <material name="blue">
    <color rgba="0 0 1 1"/>
  </material>
  <material name="green">
    <color rgba="0 1 0 1"/>
  </material>
  <material name="yellow">
    <color rgba="1 1 0 1"/>
    <!-- Amarillo opaco -->
  </material>
  <material name="purple">
    <color rgba="0.5 0 0.5 1"/>
    <!-- Púrpura opaco -->
  </material>
  <!-- Enlaces y Joints -->
  <link name="base_footprint"/>
  <link name="base_link">
    <inertial>
      <origin rpy="0.0 0.25 0.3" xyz="0 0 0.04"/>
      <mass value="8.2573504e-01"/>
      <inertia ixx="2.2124416e-02" ixy="-1.2294101e-04" ixz="3.4938785e-04" iyy="2.1193702e-02" iyz="-5.0120904e-05" izz="2.0064271e-02"/>
    </inertial>
    <visual>
      <origin rpy="0 0 0" xyz="0 0 0"/>
      <geometry>
        <mesh filename="package://difrobot_description/meshes/base_link.STL"/>
      </geometry>
      <material name="blue"/>
      <!-- Asignar color azul -->
    </visual>
    <collision>
      <origin rpy="0 0 0" xyz="0 0 0"/>
      <geometry>
        <mesh filename="package://difrobot_description/meshes/base_link.STL"/>
      </geometry>
    </collision>
  </link>
  <joint name="base_joint" type="fixed">
    <parent link="base_footprint"/>
    <child link="base_link"/>
    <origin rpy="0 0 0" xyz="0 0 0.033"/>
  </joint>
  <link name="wheel_right_link">
    <inertial>
      <origin rpy="0 0 0" xyz="0 -0.014 0"/>
      <mass value="0.0530086090966721"/>
      <inertia ixx="1.88176298336665E-05" ixy="-4.8444933029987E-10" ixz="1.88163708851143E-08" iyy="3.11510738647764E-05" iyz="-6.93560663069607E-11" izz="1.8801969558182E-05"/>
    </inertial>
    <visual>
      <origin rpy="1.57 0 0" xyz="0 0 0"/>
      <geometry>
        <mesh filename="package://difrobot_description/meshes/wheel_right_link.STL"/>
      </geometry>
      <material name="green"/>
      <!-- Asignar color verde -->
    </visual>
    <collision>
      <origin rpy="1.57 0 0" xyz="0 -0.015 0"/>
      <geometry>
        <sphere radius="0.033"/>
      </geometry>
    </collision>
  </link>
  <joint name="wheel_right_joint" type="continuous">
    <origin rpy="0 0 0" xyz="0 -0.0701101849418637 0"/>
    <parent link="base_link"/>
    <child link="wheel_right_link"/>
    <axis xyz="0 1 0"/>
  </joint>
  <link name="wheel_left_link">
    <inertial>
      <origin rpy="0 0 0" xyz="0 0.014 0"/>
      <mass value="0.0530086043217644"/>
      <inertia ixx="1.8792911368909E-05" ixy="3.31256392204584E-10" ixz="-1.14082001662767E-08" iyy="3.11510738759073E-05" iyz="-3.60499245082192E-10" izz="1.88266886146847E-05"/>
    </inertial>
    <visual>
      <origin rpy="-1.57 0 0" xyz="0 0 0"/>
      <geometry>
        <mesh filename="package://difrobot_description/meshes/wheel_left_link.STL"/>
      </geometry>
      <material name="green"/>
      <!-- Asignar color verde -->
    </visual>
    <collision>
      <origin rpy="-1.57 0 0" xyz="0 0.015 0"/>
      <geometry>
        <sphere radius="0.033"/>
      </geometry>
    </collision>
  </link>
  <joint name="wheel_left_joint" type="continuous">
    <origin rpy="0 0 0" xyz="0 0.0701101849418642 0"/>
    <parent link="base_link"/>
    <child link="wheel_left_link"/>
    <axis xyz="0 1 0"/>
  </joint>
  <link name="caster_front_link">
    <inertial>
      <origin rpy="0 0 0" xyz="3.89968128948481E-07 2.40073004698083E-07 0.00219173397061506"/>
      <mass value="1.44379265037903E-06"/>
      <inertia ixx="7.23075276010246E-11" ixy="-6.10956883467859E-16" ixz="2.22849693525031E-15" iyy="3.8713793085917E-11" iyz="2.93909858781952E-15" izz="1.00967486676306E-10"/>
    </inertial>
    <visual>
      <origin rpy="0 0 0" xyz="0 0 0"/>
      <geometry>
        <mesh filename="package://difrobot_description/meshes/caster_front_link.STL"/>
      </geometry>
      <material name="yellow"/>
      <!-- Asignar color amarillo -->
    </visual>
    <collision>
      <origin rpy="0 0 0" xyz="0 0 0"/>
      <geometry>
        <sphere radius="0.005"/>
      </geometry>
    </collision>
  </link>
  <joint name="caster_front_joint" type="fixed">
    <origin rpy="0 0 0" xyz="0.04755 0 -0.0275"/>
    <parent link="base_link"/>
    <child link="caster_front_link"/>
    <axis xyz="0 0 0"/>
  </joint>
  <link name="caster_rear_link">
    <inertial>
      <origin rpy="0 0 0" xyz="3.8996812895542E-07 2.40073004698083E-07 0.00219173397061509"/>
      <mass value="1.44379265037902E-06"/>
      <inertia ixx="7.23075276010246E-11" ixy="-6.10956872363424E-16" ixz="2.22849693527207E-15" iyy="3.87137930859167E-11" iyz="2.939098587861E-15" izz="1.00967486676306E-10"/>
    </inertial>
    <visual>
      <origin rpy="0 0 0" xyz="0 0 0"/>
      <geometry>
        <mesh filename="package://difrobot_description/meshes/caster_rear_link.STL"/>
      </geometry>
      <material name="purple"/>
      <!-- Asignar color púrpura -->
    </visual>
    <collision>
      <origin rpy="0 0 0" xyz="0 0 0"/>
      <geometry>
        <sphere radius="0.005"/>
      </geometry>
    </collision>
  </link>
  <joint name="caster_rear_joint" type="fixed">
    <origin rpy="0 0 0" xyz="-0.04755 0 -0.0275"/>
    <parent link="base_link"/>
    <child link="caster_rear_link"/>
    <axis xyz="0 0 0"/>
  </joint>
</robot>
